{
  "nbformat": 4,
  "nbformat_minor": 0,
  "metadata": {
    "colab": {
      "name": "clone_github.ipynb",
      "provenance": [],
      "mount_file_id": "1AP_-mNksZrXhQlj0TPSNbiihZaGAHrAN",
      "authorship_tag": "ABX9TyOk2y44r+deGEW2L4ZIJJ46",
      "include_colab_link": true
    },
    "kernelspec": {
      "name": "python3",
      "display_name": "Python 3"
    },
    "language_info": {
      "name": "python"
    }
  },
  "cells": [
    {
      "cell_type": "markdown",
      "metadata": {
        "id": "view-in-github",
        "colab_type": "text"
      },
      "source": [
        "<a href=\"https://colab.research.google.com/github/srinivaschalamala/arcface-keras1/blob/master/clone_github.ipynb\" target=\"_parent\"><img src=\"https://colab.research.google.com/assets/colab-badge.svg\" alt=\"Open In Colab\"/></a>"
      ]
    },
    {
      "cell_type": "code",
      "metadata": {
        "id": "r_JIJalAOF39"
      },
      "source": [
        ""
      ],
      "execution_count": null,
      "outputs": []
    },
    {
      "cell_type": "code",
      "metadata": {
        "colab": {
          "base_uri": "https://localhost:8080/",
          "height": 911
        },
        "id": "G253S4-lK32b",
        "outputId": "7ff1b881-f19a-45da-b089-563790d0a158"
      },
      "source": [
        "from google.colab import drive\n",
        "drive.mount('/content/gdrive',force_remount=True )\n",
        "% pwd\n",
        "% cd gdrive\n",
        "% pwd\n",
        "% cd MyDrive/\n",
        "% pwd\n",
        "% cd Colab_projects/arcface_Oct"
      ],
      "execution_count": null,
      "outputs": [
        {
          "output_type": "stream",
          "name": "stderr",
          "text": [
            "ERROR:root:Internal Python error in the inspect module.\n",
            "Below is the traceback from this internal error.\n",
            "\n"
          ]
        },
        {
          "output_type": "stream",
          "name": "stdout",
          "text": [
            "Mounted at /content/gdrive\n",
            "Traceback (most recent call last):\n",
            "  File \"/usr/local/lib/python3.7/dist-packages/IPython/core/interactiveshell.py\", line 2882, in run_code\n",
            "    exec(code_obj, self.user_global_ns, self.user_ns)\n",
            "  File \"<ipython-input-6-594d3c9a5fb4>\", line 3, in <module>\n",
            "    get_ipython().magic('pwd')\n",
            "  File \"/usr/local/lib/python3.7/dist-packages/IPython/core/interactiveshell.py\", line 2160, in magic\n",
            "    return self.run_line_magic(magic_name, magic_arg_s)\n",
            "  File \"/usr/local/lib/python3.7/dist-packages/IPython/core/interactiveshell.py\", line 2081, in run_line_magic\n",
            "    result = fn(*args,**kwargs)\n",
            "  File \"<decorator-gen-83>\", line 2, in pwd\n",
            "  File \"/usr/local/lib/python3.7/dist-packages/IPython/core/magic.py\", line 188, in <lambda>\n",
            "    call = lambda f, *a, **k: f(*a, **k)\n",
            "  File \"/usr/local/lib/python3.7/dist-packages/IPython/core/magics/osm.py\", line 244, in pwd\n",
            "    return py3compat.getcwd()\n",
            "OSError: [Errno 107] Transport endpoint is not connected\n",
            "\n",
            "During handling of the above exception, another exception occurred:\n",
            "\n",
            "Traceback (most recent call last):\n",
            "  File \"/usr/local/lib/python3.7/dist-packages/IPython/core/interactiveshell.py\", line 1823, in showtraceback\n",
            "    stb = value._render_traceback_()\n",
            "AttributeError: 'OSError' object has no attribute '_render_traceback_'\n",
            "\n",
            "During handling of the above exception, another exception occurred:\n",
            "\n",
            "Traceback (most recent call last):\n",
            "  File \"/usr/local/lib/python3.7/dist-packages/IPython/core/ultratb.py\", line 1132, in get_records\n",
            "    return _fixed_getinnerframes(etb, number_of_lines_of_context, tb_offset)\n",
            "  File \"/usr/local/lib/python3.7/dist-packages/IPython/core/ultratb.py\", line 313, in wrapped\n",
            "    return f(*args, **kwargs)\n",
            "  File \"/usr/local/lib/python3.7/dist-packages/IPython/core/ultratb.py\", line 358, in _fixed_getinnerframes\n",
            "    records = fix_frame_records_filenames(inspect.getinnerframes(etb, context))\n",
            "  File \"/usr/lib/python3.7/inspect.py\", line 1502, in getinnerframes\n",
            "    frameinfo = (tb.tb_frame,) + getframeinfo(tb, context)\n",
            "  File \"/usr/lib/python3.7/inspect.py\", line 1460, in getframeinfo\n",
            "    filename = getsourcefile(frame) or getfile(frame)\n",
            "  File \"/usr/lib/python3.7/inspect.py\", line 696, in getsourcefile\n",
            "    if getattr(getmodule(object, filename), '__loader__', None) is not None:\n",
            "  File \"/usr/lib/python3.7/inspect.py\", line 725, in getmodule\n",
            "    file = getabsfile(object, _filename)\n",
            "  File \"/usr/lib/python3.7/inspect.py\", line 709, in getabsfile\n",
            "    return os.path.normcase(os.path.abspath(_filename))\n",
            "  File \"/usr/lib/python3.7/posixpath.py\", line 383, in abspath\n",
            "    cwd = os.getcwd()\n",
            "OSError: [Errno 107] Transport endpoint is not connected\n"
          ]
        },
        {
          "output_type": "error",
          "ename": "OSError",
          "evalue": "ignored",
          "traceback": [
            "\u001b[0;31m---------------------------------------------------------------------------\u001b[0m"
          ]
        }
      ]
    }
  ]
}